2024-11-09 16:24:06,865 | INFO | test_challenge выполнен успешно
2024-11-09 16:24:06,865 | WARNING | Неверный тип данных для объекта Runner
Traceback (most recent call last):
  File "D:\User\Dekstop\Python\ProjectsPython\NewProjects\test_12_4\test_12_4.py", line 23, in test_run
    runner2 = Runner(22)
              ^^^^^^^^^^
  File "D:\User\Dekstop\Python\ProjectsPython\NewProjects\test_12_4\rt_with_exceptions.py", line 6, in __init__
    raise TypeError(f'Имя может быть только строкой, передано {type(name).__name__}')
TypeError: Имя может быть только строкой, передано int
2024-11-09 16:24:06,865 | INFO | test_walk was completed successfully
NoneType: None
